
Date: 2022-07-24 22:42:14.631261

[send_post]---->Traceback (most recent call last):
  File "c:\code\bot_swiss\bot.py", line 129, in send_post
    bot.forward_message(281321076, CHANNEL_ID, message_id)
  File "C:\Users\mdpru\AppData\Local\Programs\Python\Python38\lib\site-packages\telebot\__init__.py", line 613, in forward_message
    apihelper.forward_message(self.token, chat_id, from_chat_id, message_id, disable_notification))
  File "C:\Users\mdpru\AppData\Local\Programs\Python\Python38\lib\site-packages\telebot\apihelper.py", line 254, in forward_message
    return _make_request(token, method_url, params=payload)
  File "C:\Users\mdpru\AppData\Local\Programs\Python\Python38\lib\site-packages\telebot\apihelper.py", line 60, in _make_request
    return _check_result(method_name, result)['result']
  File "C:\Users\mdpru\AppData\Local\Programs\Python\Python38\lib\site-packages\telebot\apihelper.py", line 79, in _check_result
    raise ApiException(msg, method_name, result)
telebot.apihelper.ApiException: A request to the Telegram API was unsuccessful. The server returned HTTP 400 Bad Request. Response body:
[b'{"ok":false,"error_code":400,"description":"Bad Request: chat not found"}']

Date: 2022-07-24 22:42:45.325708

[send_post]---->Traceback (most recent call last):
  File "c:\code\bot_swiss\bot.py", line 129, in send_post
    bot.forward_message(281321076, CHANNEL_ID, message_id)
  File "C:\Users\mdpru\AppData\Local\Programs\Python\Python38\lib\site-packages\telebot\__init__.py", line 613, in forward_message
    apihelper.forward_message(self.token, chat_id, from_chat_id, message_id, disable_notification))
  File "C:\Users\mdpru\AppData\Local\Programs\Python\Python38\lib\site-packages\telebot\apihelper.py", line 254, in forward_message
    return _make_request(token, method_url, params=payload)
  File "C:\Users\mdpru\AppData\Local\Programs\Python\Python38\lib\site-packages\telebot\apihelper.py", line 60, in _make_request
    return _check_result(method_name, result)['result']
  File "C:\Users\mdpru\AppData\Local\Programs\Python\Python38\lib\site-packages\telebot\apihelper.py", line 79, in _check_result
    raise ApiException(msg, method_name, result)
telebot.apihelper.ApiException: A request to the Telegram API was unsuccessful. The server returned HTTP 400 Bad Request. Response body:
[b'{"ok":false,"error_code":400,"description":"Bad Request: chat not found"}']

Date: 2022-07-24 22:43:16.246671

[send_post]---->Traceback (most recent call last):
  File "c:\code\bot_swiss\bot.py", line 129, in send_post
    bot.forward_message(281321076, CHANNEL_ID, message_id)
  File "C:\Users\mdpru\AppData\Local\Programs\Python\Python38\lib\site-packages\telebot\__init__.py", line 613, in forward_message
    apihelper.forward_message(self.token, chat_id, from_chat_id, message_id, disable_notification))
  File "C:\Users\mdpru\AppData\Local\Programs\Python\Python38\lib\site-packages\telebot\apihelper.py", line 254, in forward_message
    return _make_request(token, method_url, params=payload)
  File "C:\Users\mdpru\AppData\Local\Programs\Python\Python38\lib\site-packages\telebot\apihelper.py", line 60, in _make_request
    return _check_result(method_name, result)['result']
  File "C:\Users\mdpru\AppData\Local\Programs\Python\Python38\lib\site-packages\telebot\apihelper.py", line 79, in _check_result
    raise ApiException(msg, method_name, result)
telebot.apihelper.ApiException: A request to the Telegram API was unsuccessful. The server returned HTTP 400 Bad Request. Response body:
[b'{"ok":false,"error_code":400,"description":"Bad Request: chat not found"}']

Date: 2022-07-24 22:43:46.869061

[send_post]---->Traceback (most recent call last):
  File "c:\code\bot_swiss\bot.py", line 129, in send_post
    bot.forward_message(281321076, CHANNEL_ID, message_id)
  File "C:\Users\mdpru\AppData\Local\Programs\Python\Python38\lib\site-packages\telebot\__init__.py", line 613, in forward_message
    apihelper.forward_message(self.token, chat_id, from_chat_id, message_id, disable_notification))
  File "C:\Users\mdpru\AppData\Local\Programs\Python\Python38\lib\site-packages\telebot\apihelper.py", line 254, in forward_message
    return _make_request(token, method_url, params=payload)
  File "C:\Users\mdpru\AppData\Local\Programs\Python\Python38\lib\site-packages\telebot\apihelper.py", line 60, in _make_request
    return _check_result(method_name, result)['result']
  File "C:\Users\mdpru\AppData\Local\Programs\Python\Python38\lib\site-packages\telebot\apihelper.py", line 79, in _check_result
    raise ApiException(msg, method_name, result)
telebot.apihelper.ApiException: A request to the Telegram API was unsuccessful. The server returned HTTP 400 Bad Request. Response body:
[b'{"ok":false,"error_code":400,"description":"Bad Request: chat not found"}']

Date: 2022-07-24 22:44:17.755942

[send_post]---->Traceback (most recent call last):
  File "c:\code\bot_swiss\bot.py", line 129, in send_post
    bot.forward_message(281321076, CHANNEL_ID, message_id)
  File "C:\Users\mdpru\AppData\Local\Programs\Python\Python38\lib\site-packages\telebot\__init__.py", line 613, in forward_message
    apihelper.forward_message(self.token, chat_id, from_chat_id, message_id, disable_notification))
  File "C:\Users\mdpru\AppData\Local\Programs\Python\Python38\lib\site-packages\telebot\apihelper.py", line 254, in forward_message
    return _make_request(token, method_url, params=payload)
  File "C:\Users\mdpru\AppData\Local\Programs\Python\Python38\lib\site-packages\telebot\apihelper.py", line 60, in _make_request
    return _check_result(method_name, result)['result']
  File "C:\Users\mdpru\AppData\Local\Programs\Python\Python38\lib\site-packages\telebot\apihelper.py", line 79, in _check_result
    raise ApiException(msg, method_name, result)
telebot.apihelper.ApiException: A request to the Telegram API was unsuccessful. The server returned HTTP 400 Bad Request. Response body:
[b'{"ok":false,"error_code":400,"description":"Bad Request: chat not found"}']

Date: 2022-07-24 22:44:48.430872

[send_post]---->Traceback (most recent call last):
  File "c:\code\bot_swiss\bot.py", line 129, in send_post
    bot.forward_message(281321076, CHANNEL_ID, message_id)
  File "C:\Users\mdpru\AppData\Local\Programs\Python\Python38\lib\site-packages\telebot\__init__.py", line 613, in forward_message
    apihelper.forward_message(self.token, chat_id, from_chat_id, message_id, disable_notification))
  File "C:\Users\mdpru\AppData\Local\Programs\Python\Python38\lib\site-packages\telebot\apihelper.py", line 254, in forward_message
    return _make_request(token, method_url, params=payload)
  File "C:\Users\mdpru\AppData\Local\Programs\Python\Python38\lib\site-packages\telebot\apihelper.py", line 60, in _make_request
    return _check_result(method_name, result)['result']
  File "C:\Users\mdpru\AppData\Local\Programs\Python\Python38\lib\site-packages\telebot\apihelper.py", line 79, in _check_result
    raise ApiException(msg, method_name, result)
telebot.apihelper.ApiException: A request to the Telegram API was unsuccessful. The server returned HTTP 400 Bad Request. Response body:
[b'{"ok":false,"error_code":400,"description":"Bad Request: chat not found"}']

Date: 2022-07-24 22:45:19.134434

[send_post]---->Traceback (most recent call last):
  File "c:\code\bot_swiss\bot.py", line 129, in send_post
    bot.forward_message(281321076, CHANNEL_ID, message_id)
  File "C:\Users\mdpru\AppData\Local\Programs\Python\Python38\lib\site-packages\telebot\__init__.py", line 613, in forward_message
    apihelper.forward_message(self.token, chat_id, from_chat_id, message_id, disable_notification))
  File "C:\Users\mdpru\AppData\Local\Programs\Python\Python38\lib\site-packages\telebot\apihelper.py", line 254, in forward_message
    return _make_request(token, method_url, params=payload)
  File "C:\Users\mdpru\AppData\Local\Programs\Python\Python38\lib\site-packages\telebot\apihelper.py", line 60, in _make_request
    return _check_result(method_name, result)['result']
  File "C:\Users\mdpru\AppData\Local\Programs\Python\Python38\lib\site-packages\telebot\apihelper.py", line 79, in _check_result
    raise ApiException(msg, method_name, result)
telebot.apihelper.ApiException: A request to the Telegram API was unsuccessful. The server returned HTTP 400 Bad Request. Response body:
[b'{"ok":false,"error_code":400,"description":"Bad Request: chat not found"}']

Date: 2022-07-24 22:45:49.937808

[send_post]---->Traceback (most recent call last):
  File "c:\code\bot_swiss\bot.py", line 129, in send_post
    bot.forward_message(281321076, CHANNEL_ID, message_id)
  File "C:\Users\mdpru\AppData\Local\Programs\Python\Python38\lib\site-packages\telebot\__init__.py", line 613, in forward_message
    apihelper.forward_message(self.token, chat_id, from_chat_id, message_id, disable_notification))
  File "C:\Users\mdpru\AppData\Local\Programs\Python\Python38\lib\site-packages\telebot\apihelper.py", line 254, in forward_message
    return _make_request(token, method_url, params=payload)
  File "C:\Users\mdpru\AppData\Local\Programs\Python\Python38\lib\site-packages\telebot\apihelper.py", line 60, in _make_request
    return _check_result(method_name, result)['result']
  File "C:\Users\mdpru\AppData\Local\Programs\Python\Python38\lib\site-packages\telebot\apihelper.py", line 79, in _check_result
    raise ApiException(msg, method_name, result)
telebot.apihelper.ApiException: A request to the Telegram API was unsuccessful. The server returned HTTP 400 Bad Request. Response body:
[b'{"ok":false,"error_code":400,"description":"Bad Request: chat not found"}']

Date: 2022-07-24 22:46:20.622115

[send_post]---->Traceback (most recent call last):
  File "c:\code\bot_swiss\bot.py", line 129, in send_post
    bot.forward_message(281321076, CHANNEL_ID, message_id)
  File "C:\Users\mdpru\AppData\Local\Programs\Python\Python38\lib\site-packages\telebot\__init__.py", line 613, in forward_message
    apihelper.forward_message(self.token, chat_id, from_chat_id, message_id, disable_notification))
  File "C:\Users\mdpru\AppData\Local\Programs\Python\Python38\lib\site-packages\telebot\apihelper.py", line 254, in forward_message
    return _make_request(token, method_url, params=payload)
  File "C:\Users\mdpru\AppData\Local\Programs\Python\Python38\lib\site-packages\telebot\apihelper.py", line 60, in _make_request
    return _check_result(method_name, result)['result']
  File "C:\Users\mdpru\AppData\Local\Programs\Python\Python38\lib\site-packages\telebot\apihelper.py", line 79, in _check_result
    raise ApiException(msg, method_name, result)
telebot.apihelper.ApiException: A request to the Telegram API was unsuccessful. The server returned HTTP 400 Bad Request. Response body:
[b'{"ok":false,"error_code":400,"description":"Bad Request: chat not found"}']

Date: 2022-07-24 22:46:51.309000

[send_post]---->Traceback (most recent call last):
  File "c:\code\bot_swiss\bot.py", line 129, in send_post
    bot.forward_message(281321076, CHANNEL_ID, message_id)
  File "C:\Users\mdpru\AppData\Local\Programs\Python\Python38\lib\site-packages\telebot\__init__.py", line 613, in forward_message
    apihelper.forward_message(self.token, chat_id, from_chat_id, message_id, disable_notification))
  File "C:\Users\mdpru\AppData\Local\Programs\Python\Python38\lib\site-packages\telebot\apihelper.py", line 254, in forward_message
    return _make_request(token, method_url, params=payload)
  File "C:\Users\mdpru\AppData\Local\Programs\Python\Python38\lib\site-packages\telebot\apihelper.py", line 60, in _make_request
    return _check_result(method_name, result)['result']
  File "C:\Users\mdpru\AppData\Local\Programs\Python\Python38\lib\site-packages\telebot\apihelper.py", line 79, in _check_result
    raise ApiException(msg, method_name, result)
telebot.apihelper.ApiException: A request to the Telegram API was unsuccessful. The server returned HTTP 400 Bad Request. Response body:
[b'{"ok":false,"error_code":400,"description":"Bad Request: chat not found"}']

Date: 2022-07-24 22:47:22.009125

[send_post]---->Traceback (most recent call last):
  File "c:\code\bot_swiss\bot.py", line 129, in send_post
    bot.forward_message(281321076, CHANNEL_ID, message_id)
  File "C:\Users\mdpru\AppData\Local\Programs\Python\Python38\lib\site-packages\telebot\__init__.py", line 613, in forward_message
    apihelper.forward_message(self.token, chat_id, from_chat_id, message_id, disable_notification))
  File "C:\Users\mdpru\AppData\Local\Programs\Python\Python38\lib\site-packages\telebot\apihelper.py", line 254, in forward_message
    return _make_request(token, method_url, params=payload)
  File "C:\Users\mdpru\AppData\Local\Programs\Python\Python38\lib\site-packages\telebot\apihelper.py", line 60, in _make_request
    return _check_result(method_name, result)['result']
  File "C:\Users\mdpru\AppData\Local\Programs\Python\Python38\lib\site-packages\telebot\apihelper.py", line 79, in _check_result
    raise ApiException(msg, method_name, result)
telebot.apihelper.ApiException: A request to the Telegram API was unsuccessful. The server returned HTTP 400 Bad Request. Response body:
[b'{"ok":false,"error_code":400,"description":"Bad Request: chat not found"}']

Date: 2022-07-24 22:47:52.938684

[send_post]---->Traceback (most recent call last):
  File "c:\code\bot_swiss\bot.py", line 129, in send_post
    bot.forward_message(281321076, CHANNEL_ID, message_id)
  File "C:\Users\mdpru\AppData\Local\Programs\Python\Python38\lib\site-packages\telebot\__init__.py", line 613, in forward_message
    apihelper.forward_message(self.token, chat_id, from_chat_id, message_id, disable_notification))
  File "C:\Users\mdpru\AppData\Local\Programs\Python\Python38\lib\site-packages\telebot\apihelper.py", line 254, in forward_message
    return _make_request(token, method_url, params=payload)
  File "C:\Users\mdpru\AppData\Local\Programs\Python\Python38\lib\site-packages\telebot\apihelper.py", line 60, in _make_request
    return _check_result(method_name, result)['result']
  File "C:\Users\mdpru\AppData\Local\Programs\Python\Python38\lib\site-packages\telebot\apihelper.py", line 79, in _check_result
    raise ApiException(msg, method_name, result)
telebot.apihelper.ApiException: A request to the Telegram API was unsuccessful. The server returned HTTP 400 Bad Request. Response body:
[b'{"ok":false,"error_code":400,"description":"Bad Request: chat not found"}']

Date: 2022-07-24 22:48:23.648972

[send_post]---->Traceback (most recent call last):
  File "c:\code\bot_swiss\bot.py", line 129, in send_post
    bot.forward_message(281321076, CHANNEL_ID, message_id)
  File "C:\Users\mdpru\AppData\Local\Programs\Python\Python38\lib\site-packages\telebot\__init__.py", line 613, in forward_message
    apihelper.forward_message(self.token, chat_id, from_chat_id, message_id, disable_notification))
  File "C:\Users\mdpru\AppData\Local\Programs\Python\Python38\lib\site-packages\telebot\apihelper.py", line 254, in forward_message
    return _make_request(token, method_url, params=payload)
  File "C:\Users\mdpru\AppData\Local\Programs\Python\Python38\lib\site-packages\telebot\apihelper.py", line 60, in _make_request
    return _check_result(method_name, result)['result']
  File "C:\Users\mdpru\AppData\Local\Programs\Python\Python38\lib\site-packages\telebot\apihelper.py", line 79, in _check_result
    raise ApiException(msg, method_name, result)
telebot.apihelper.ApiException: A request to the Telegram API was unsuccessful. The server returned HTTP 400 Bad Request. Response body:
[b'{"ok":false,"error_code":400,"description":"Bad Request: chat not found"}']

Date: 2022-07-24 22:48:54.286891

[send_post]---->Traceback (most recent call last):
  File "c:\code\bot_swiss\bot.py", line 129, in send_post
    bot.forward_message(281321076, CHANNEL_ID, message_id)
  File "C:\Users\mdpru\AppData\Local\Programs\Python\Python38\lib\site-packages\telebot\__init__.py", line 613, in forward_message
    apihelper.forward_message(self.token, chat_id, from_chat_id, message_id, disable_notification))
  File "C:\Users\mdpru\AppData\Local\Programs\Python\Python38\lib\site-packages\telebot\apihelper.py", line 254, in forward_message
    return _make_request(token, method_url, params=payload)
  File "C:\Users\mdpru\AppData\Local\Programs\Python\Python38\lib\site-packages\telebot\apihelper.py", line 60, in _make_request
    return _check_result(method_name, result)['result']
  File "C:\Users\mdpru\AppData\Local\Programs\Python\Python38\lib\site-packages\telebot\apihelper.py", line 79, in _check_result
    raise ApiException(msg, method_name, result)
telebot.apihelper.ApiException: A request to the Telegram API was unsuccessful. The server returned HTTP 400 Bad Request. Response body:
[b'{"ok":false,"error_code":400,"description":"Bad Request: chat not found"}']

Date: 2022-07-24 22:49:25.011383

[send_post]---->Traceback (most recent call last):
  File "c:\code\bot_swiss\bot.py", line 129, in send_post
    bot.forward_message(281321076, CHANNEL_ID, message_id)
  File "C:\Users\mdpru\AppData\Local\Programs\Python\Python38\lib\site-packages\telebot\__init__.py", line 613, in forward_message
    apihelper.forward_message(self.token, chat_id, from_chat_id, message_id, disable_notification))
  File "C:\Users\mdpru\AppData\Local\Programs\Python\Python38\lib\site-packages\telebot\apihelper.py", line 254, in forward_message
    return _make_request(token, method_url, params=payload)
  File "C:\Users\mdpru\AppData\Local\Programs\Python\Python38\lib\site-packages\telebot\apihelper.py", line 60, in _make_request
    return _check_result(method_name, result)['result']
  File "C:\Users\mdpru\AppData\Local\Programs\Python\Python38\lib\site-packages\telebot\apihelper.py", line 79, in _check_result
    raise ApiException(msg, method_name, result)
telebot.apihelper.ApiException: A request to the Telegram API was unsuccessful. The server returned HTTP 400 Bad Request. Response body:
[b'{"ok":false,"error_code":400,"description":"Bad Request: chat not found"}']

Date: 2022-07-24 22:49:55.597542

[send_post]---->Traceback (most recent call last):
  File "c:\code\bot_swiss\bot.py", line 129, in send_post
    bot.forward_message(281321076, CHANNEL_ID, message_id)
  File "C:\Users\mdpru\AppData\Local\Programs\Python\Python38\lib\site-packages\telebot\__init__.py", line 613, in forward_message
    apihelper.forward_message(self.token, chat_id, from_chat_id, message_id, disable_notification))
  File "C:\Users\mdpru\AppData\Local\Programs\Python\Python38\lib\site-packages\telebot\apihelper.py", line 254, in forward_message
    return _make_request(token, method_url, params=payload)
  File "C:\Users\mdpru\AppData\Local\Programs\Python\Python38\lib\site-packages\telebot\apihelper.py", line 60, in _make_request
    return _check_result(method_name, result)['result']
  File "C:\Users\mdpru\AppData\Local\Programs\Python\Python38\lib\site-packages\telebot\apihelper.py", line 79, in _check_result
    raise ApiException(msg, method_name, result)
telebot.apihelper.ApiException: A request to the Telegram API was unsuccessful. The server returned HTTP 400 Bad Request. Response body:
[b'{"ok":false,"error_code":400,"description":"Bad Request: chat not found"}']

Date: 2022-08-05 18:26:56.665657

[get_accounts][account_tb]---->ОШИБКА:  отношение "account_tb" не существует
LINE 1: ...guage  ,        feedback_st  , timer_conv  FROM   account_tb...
                                                             ^

Date: 2022-08-05 18:27:23.275937

[get_accounts][account_tb]---->ОШИБКА:  отношение "account_tb" не существует
LINE 1: ...guage  ,        feedback_st  , timer_conv  FROM   account_tb...
                                                             ^

Date: 2022-08-05 18:27:56.030359

[send_post]---->Traceback (most recent call last):
  File "c:\code\bot_swiss\bot.py", line 129, in send_post
    bot.forward_message(281321076, CHANNEL_ID, message_id)
  File "C:\Users\mdpru\AppData\Local\Programs\Python\Python38\lib\site-packages\telebot\__init__.py", line 613, in forward_message
    apihelper.forward_message(self.token, chat_id, from_chat_id, message_id, disable_notification))
  File "C:\Users\mdpru\AppData\Local\Programs\Python\Python38\lib\site-packages\telebot\apihelper.py", line 254, in forward_message
    return _make_request(token, method_url, params=payload)
  File "C:\Users\mdpru\AppData\Local\Programs\Python\Python38\lib\site-packages\telebot\apihelper.py", line 60, in _make_request
    return _check_result(method_name, result)['result']
  File "C:\Users\mdpru\AppData\Local\Programs\Python\Python38\lib\site-packages\telebot\apihelper.py", line 79, in _check_result
    raise ApiException(msg, method_name, result)
telebot.apihelper.ApiException: A request to the Telegram API was unsuccessful. The server returned HTTP 400 Bad Request. Response body:
[b'{"ok":false,"error_code":400,"description":"Bad Request: chat not found"}']

Date: 2022-08-05 18:28:26.556474

[send_post]---->Traceback (most recent call last):
  File "c:\code\bot_swiss\bot.py", line 129, in send_post
    bot.forward_message(281321076, CHANNEL_ID, message_id)
  File "C:\Users\mdpru\AppData\Local\Programs\Python\Python38\lib\site-packages\telebot\__init__.py", line 613, in forward_message
    apihelper.forward_message(self.token, chat_id, from_chat_id, message_id, disable_notification))
  File "C:\Users\mdpru\AppData\Local\Programs\Python\Python38\lib\site-packages\telebot\apihelper.py", line 254, in forward_message
    return _make_request(token, method_url, params=payload)
  File "C:\Users\mdpru\AppData\Local\Programs\Python\Python38\lib\site-packages\telebot\apihelper.py", line 60, in _make_request
    return _check_result(method_name, result)['result']
  File "C:\Users\mdpru\AppData\Local\Programs\Python\Python38\lib\site-packages\telebot\apihelper.py", line 79, in _check_result
    raise ApiException(msg, method_name, result)
telebot.apihelper.ApiException: A request to the Telegram API was unsuccessful. The server returned HTTP 400 Bad Request. Response body:
[b'{"ok":false,"error_code":400,"description":"Bad Request: chat not found"}']

Date: 2022-08-05 18:29:43.565351

[get_accounts][account_tb]---->ОШИБКА:  отношение "account_tb" не существует
LINE 1: ...guage  ,        feedback_st  , timer_conv  FROM   account_tb...
                                                             ^

Date: 2022-08-05 18:29:50.716863

[get_accounts][account_tb]---->ОШИБКА:  отношение "account_tb" не существует
LINE 1: ...guage  ,        feedback_st  , timer_conv  FROM   account_tb...
                                                             ^

Date: 2022-08-05 18:29:50.783821

[create_db]---->Traceback (most recent call last):
  File "c:\code\bot_swiss\database.py", line 490, in get_accounts
    cur.execute("SELECT telegram_id  , login     , "
psycopg2.errors.UndefinedTable: ОШИБКА:  отношение "account_tb" не существует
LINE 1: ...guage  ,        feedback_st  , timer_conv  FROM   account_tb...
                                                             ^


During handling of the above exception, another exception occurred:

Traceback (most recent call last):
  File "c:\code\bot_swiss\database.py", line 539, in create_db
    cur.execute(com)
psycopg2.errors.DuplicateTable: ОШИБКА:  отношение "account_tb" уже существует


Date: 2022-08-05 18:30:10.618374

[get_accounts][account_tb]---->ОШИБКА:  отношение "account_tb" не существует
LINE 1: ...guage  ,        feedback_st  , timer_conv  FROM   account_tb...
                                                             ^

Date: 2022-08-05 18:30:21.734910

[send_post]---->Traceback (most recent call last):
  File "c:\code\bot_swiss\bot.py", line 129, in send_post
    bot.forward_message(281321076, CHANNEL_ID, message_id)
  File "C:\Users\mdpru\AppData\Local\Programs\Python\Python38\lib\site-packages\telebot\__init__.py", line 613, in forward_message
    apihelper.forward_message(self.token, chat_id, from_chat_id, message_id, disable_notification))
  File "C:\Users\mdpru\AppData\Local\Programs\Python\Python38\lib\site-packages\telebot\apihelper.py", line 254, in forward_message
    return _make_request(token, method_url, params=payload)
  File "C:\Users\mdpru\AppData\Local\Programs\Python\Python38\lib\site-packages\telebot\apihelper.py", line 60, in _make_request
    return _check_result(method_name, result)['result']
  File "C:\Users\mdpru\AppData\Local\Programs\Python\Python38\lib\site-packages\telebot\apihelper.py", line 79, in _check_result
    raise ApiException(msg, method_name, result)
telebot.apihelper.ApiException: A request to the Telegram API was unsuccessful. The server returned HTTP 400 Bad Request. Response body:
[b'{"ok":false,"error_code":400,"description":"Bad Request: chat not found"}']

Date: 2022-08-05 18:30:36.846903

[get_accounts][account_tb]---->ОШИБКА:  отношение "account_tb" не существует
LINE 1: ...guage  ,        feedback_st  , timer_conv  FROM   account_tb...
                                                             ^
